<?xml version="1.0" ?>
<robot name="partnet_98bc3afca001f433a1702a37604ec6f">
	<link name="base"/>
	<link name="link_0">
		<visual name="body-1">
			<origin xyz="-0.007957159617363499 -0.04936375154296074 0.6252384595433996"/>
			<geometry>
				<mesh filename="textured_objs/original-10.obj"/>
			</geometry>
		</visual>
		<visual name="body-1">
			<origin xyz="-0.007957159617363499 -0.04936375154296074 0.6252384595433996"/>
			<geometry>
				<mesh filename="textured_objs/original-20.obj"/>
			</geometry>
		</visual>
		<visual name="body-1">
			<origin xyz="-0.007957159617363499 -0.04936375154296074 0.6252384595433996"/>
			<geometry>
				<mesh filename="textured_objs/original-21.obj"/>
			</geometry>
		</visual>
		<visual name="body-1">
			<origin xyz="-0.007957159617363499 -0.04936375154296074 0.6252384595433996"/>
			<geometry>
				<mesh filename="textured_objs/original-22.obj"/>
			</geometry>
		</visual>
		<visual name="body-1">
			<origin xyz="-0.007957159617363499 -0.04936375154296074 0.6252384595433996"/>
			<geometry>
				<mesh filename="textured_objs/original-23.obj"/>
			</geometry>
		</visual>
		<visual name="body-1">
			<origin xyz="-0.007957159617363499 -0.04936375154296074 0.6252384595433996"/>
			<geometry>
				<mesh filename="textured_objs/original-24.obj"/>
			</geometry>
		</visual>
		<visual name="body-1">
			<origin xyz="-0.007957159617363499 -0.04936375154296074 0.6252384595433996"/>
			<geometry>
				<mesh filename="textured_objs/original-25.obj"/>
			</geometry>
		</visual>
		<visual name="body-1">
			<origin xyz="-0.007957159617363499 -0.04936375154296074 0.6252384595433996"/>
			<geometry>
				<mesh filename="textured_objs/original-35.obj"/>
			</geometry>
		</visual>
		<visual name="body-1">
			<origin xyz="-0.007957159617363499 -0.04936375154296074 0.6252384595433996"/>
			<geometry>
				<mesh filename="textured_objs/original-14.obj"/>
			</geometry>
		</visual>
		<visual name="body-1">
			<origin xyz="-0.007957159617363499 -0.04936375154296074 0.6252384595433996"/>
			<geometry>
				<mesh filename="textured_objs/original-15.obj"/>
			</geometry>
		</visual>
		<visual name="body-1">
			<origin xyz="-0.007957159617363499 -0.04936375154296074 0.6252384595433996"/>
			<geometry>
				<mesh filename="textured_objs/original-16.obj"/>
			</geometry>
		</visual>
		<visual name="body-1">
			<origin xyz="-0.007957159617363499 -0.04936375154296074 0.6252384595433996"/>
			<geometry>
				<mesh filename="textured_objs/original-17.obj"/>
			</geometry>
		</visual>
		<visual name="body-1">
			<origin xyz="-0.007957159617363499 -0.04936375154296074 0.6252384595433996"/>
			<geometry>
				<mesh filename="textured_objs/original-18.obj"/>
			</geometry>
		</visual>
		<visual name="body-1">
			<origin xyz="-0.007957159617363499 -0.04936375154296074 0.6252384595433996"/>
			<geometry>
				<mesh filename="textured_objs/original-19.obj"/>
			</geometry>
		</visual>
		<visual name="body-1">
			<origin xyz="-0.007957159617363499 -0.04936375154296074 0.6252384595433996"/>
			<geometry>
				<mesh filename="textured_objs/original-26.obj"/>
			</geometry>
		</visual>
		<visual name="body-1">
			<origin xyz="-0.007957159617363499 -0.04936375154296074 0.6252384595433996"/>
			<geometry>
				<mesh filename="textured_objs/original-27.obj"/>
			</geometry>
		</visual>
		<visual name="body-1">
			<origin xyz="-0.007957159617363499 -0.04936375154296074 0.6252384595433996"/>
			<geometry>
				<mesh filename="textured_objs/original-28.obj"/>
			</geometry>
		</visual>
		<visual name="body-1">
			<origin xyz="-0.007957159617363499 -0.04936375154296074 0.6252384595433996"/>
			<geometry>
				<mesh filename="textured_objs/original-29.obj"/>
			</geometry>
		</visual>
		<visual name="body-1">
			<origin xyz="-0.007957159617363499 -0.04936375154296074 0.6252384595433996"/>
			<geometry>
				<mesh filename="textured_objs/original-30.obj"/>
			</geometry>
		</visual>
		<visual name="body-1">
			<origin xyz="-0.007957159617363499 -0.04936375154296074 0.6252384595433996"/>
			<geometry>
				<mesh filename="textured_objs/original-11.obj"/>
			</geometry>
		</visual>
		<visual name="body-1">
			<origin xyz="-0.007957159617363499 -0.04936375154296074 0.6252384595433996"/>
			<geometry>
				<mesh filename="textured_objs/original-31.obj"/>
			</geometry>
		</visual>
		<visual name="body-1">
			<origin xyz="-0.007957159617363499 -0.04936375154296074 0.6252384595433996"/>
			<geometry>
				<mesh filename="textured_objs/original-32.obj"/>
			</geometry>
		</visual>
		<visual name="body-1">
			<origin xyz="-0.007957159617363499 -0.04936375154296074 0.6252384595433996"/>
			<geometry>
				<mesh filename="textured_objs/original-33.obj"/>
			</geometry>
		</visual>
		<visual name="body-1">
			<origin xyz="-0.007957159617363499 -0.04936375154296074 0.6252384595433996"/>
			<geometry>
				<mesh filename="textured_objs/original-34.obj"/>
			</geometry>
		</visual>
		<visual name="body-1">
			<origin xyz="-0.007957159617363499 -0.04936375154296074 0.6252384595433996"/>
			<geometry>
				<mesh filename="textured_objs/original-40.obj"/>
			</geometry>
		</visual>
		<visual name="body-1">
			<origin xyz="-0.007957159617363499 -0.04936375154296074 0.6252384595433996"/>
			<geometry>
				<mesh filename="textured_objs/original-49.obj"/>
			</geometry>
		</visual>
		<visual name="body-1">
			<origin xyz="-0.007957159617363499 -0.04936375154296074 0.6252384595433996"/>
			<geometry>
				<mesh filename="textured_objs/original-48.obj"/>
			</geometry>
		</visual>
		<visual name="body-1">
			<origin xyz="-0.007957159617363499 -0.04936375154296074 0.6252384595433996"/>
			<geometry>
				<mesh filename="textured_objs/original-47.obj"/>
			</geometry>
		</visual>
		<visual name="body-1">
			<origin xyz="-0.007957159617363499 -0.04936375154296074 0.6252384595433996"/>
			<geometry>
				<mesh filename="textured_objs/original-46.obj"/>
			</geometry>
		</visual>
		<visual name="body-1">
			<origin xyz="-0.007957159617363499 -0.04936375154296074 0.6252384595433996"/>
			<geometry>
				<mesh filename="textured_objs/original-45.obj"/>
			</geometry>
		</visual>
		<visual name="body-1">
			<origin xyz="-0.007957159617363499 -0.04936375154296074 0.6252384595433996"/>
			<geometry>
				<mesh filename="textured_objs/original-44.obj"/>
			</geometry>
		</visual>
		<visual name="body-1">
			<origin xyz="-0.007957159617363499 -0.04936375154296074 0.6252384595433996"/>
			<geometry>
				<mesh filename="textured_objs/original-43.obj"/>
			</geometry>
		</visual>
		<visual name="body-1">
			<origin xyz="-0.007957159617363499 -0.04936375154296074 0.6252384595433996"/>
			<geometry>
				<mesh filename="textured_objs/original-41.obj"/>
			</geometry>
		</visual>
		<visual name="body-1">
			<origin xyz="-0.007957159617363499 -0.04936375154296074 0.6252384595433996"/>
			<geometry>
				<mesh filename="textured_objs/original-42.obj"/>
			</geometry>
		</visual>
		<visual name="body-1">
			<origin xyz="-0.007957159617363499 -0.04936375154296074 0.6252384595433996"/>
			<geometry>
				<mesh filename="textured_objs/original-50.obj"/>
			</geometry>
		</visual>
		<collision>
			<origin xyz="-0.007957159617363499 -0.04936375154296074 0.6252384595433996"/>
			<geometry>
				<mesh filename="textured_objs/original-10.obj"/>
			</geometry>
		</collision>
		<collision>
			<origin xyz="-0.007957159617363499 -0.04936375154296074 0.6252384595433996"/>
			<geometry>
				<mesh filename="textured_objs/original-20.obj"/>
			</geometry>
		</collision>
		<collision>
			<origin xyz="-0.007957159617363499 -0.04936375154296074 0.6252384595433996"/>
			<geometry>
				<mesh filename="textured_objs/original-21.obj"/>
			</geometry>
		</collision>
		<collision>
			<origin xyz="-0.007957159617363499 -0.04936375154296074 0.6252384595433996"/>
			<geometry>
				<mesh filename="textured_objs/original-22.obj"/>
			</geometry>
		</collision>
		<collision>
			<origin xyz="-0.007957159617363499 -0.04936375154296074 0.6252384595433996"/>
			<geometry>
				<mesh filename="textured_objs/original-23.obj"/>
			</geometry>
		</collision>
		<collision>
			<origin xyz="-0.007957159617363499 -0.04936375154296074 0.6252384595433996"/>
			<geometry>
				<mesh filename="textured_objs/original-24.obj"/>
			</geometry>
		</collision>
		<collision>
			<origin xyz="-0.007957159617363499 -0.04936375154296074 0.6252384595433996"/>
			<geometry>
				<mesh filename="textured_objs/original-25.obj"/>
			</geometry>
		</collision>
		<collision>
			<origin xyz="-0.007957159617363499 -0.04936375154296074 0.6252384595433996"/>
			<geometry>
				<mesh filename="textured_objs/original-35.obj"/>
			</geometry>
		</collision>
		<collision>
			<origin xyz="-0.007957159617363499 -0.04936375154296074 0.6252384595433996"/>
			<geometry>
				<mesh filename="textured_objs/original-14.obj"/>
			</geometry>
		</collision>
		<collision>
			<origin xyz="-0.007957159617363499 -0.04936375154296074 0.6252384595433996"/>
			<geometry>
				<mesh filename="textured_objs/original-15.obj"/>
			</geometry>
		</collision>
		<collision>
			<origin xyz="-0.007957159617363499 -0.04936375154296074 0.6252384595433996"/>
			<geometry>
				<mesh filename="textured_objs/original-16.obj"/>
			</geometry>
		</collision>
		<collision>
			<origin xyz="-0.007957159617363499 -0.04936375154296074 0.6252384595433996"/>
			<geometry>
				<mesh filename="textured_objs/original-17.obj"/>
			</geometry>
		</collision>
		<collision>
			<origin xyz="-0.007957159617363499 -0.04936375154296074 0.6252384595433996"/>
			<geometry>
				<mesh filename="textured_objs/original-18.obj"/>
			</geometry>
		</collision>
		<collision>
			<origin xyz="-0.007957159617363499 -0.04936375154296074 0.6252384595433996"/>
			<geometry>
				<mesh filename="textured_objs/original-19.obj"/>
			</geometry>
		</collision>
		<collision>
			<origin xyz="-0.007957159617363499 -0.04936375154296074 0.6252384595433996"/>
			<geometry>
				<mesh filename="textured_objs/original-26.obj"/>
			</geometry>
		</collision>
		<collision>
			<origin xyz="-0.007957159617363499 -0.04936375154296074 0.6252384595433996"/>
			<geometry>
				<mesh filename="textured_objs/original-27.obj"/>
			</geometry>
		</collision>
		<collision>
			<origin xyz="-0.007957159617363499 -0.04936375154296074 0.6252384595433996"/>
			<geometry>
				<mesh filename="textured_objs/original-28.obj"/>
			</geometry>
		</collision>
		<collision>
			<origin xyz="-0.007957159617363499 -0.04936375154296074 0.6252384595433996"/>
			<geometry>
				<mesh filename="textured_objs/original-29.obj"/>
			</geometry>
		</collision>
		<collision>
			<origin xyz="-0.007957159617363499 -0.04936375154296074 0.6252384595433996"/>
			<geometry>
				<mesh filename="textured_objs/original-30.obj"/>
			</geometry>
		</collision>
		<collision>
			<origin xyz="-0.007957159617363499 -0.04936375154296074 0.6252384595433996"/>
			<geometry>
				<mesh filename="textured_objs/original-11.obj"/>
			</geometry>
		</collision>
		<collision>
			<origin xyz="-0.007957159617363499 -0.04936375154296074 0.6252384595433996"/>
			<geometry>
				<mesh filename="textured_objs/original-31.obj"/>
			</geometry>
		</collision>
		<collision>
			<origin xyz="-0.007957159617363499 -0.04936375154296074 0.6252384595433996"/>
			<geometry>
				<mesh filename="textured_objs/original-32.obj"/>
			</geometry>
		</collision>
		<collision>
			<origin xyz="-0.007957159617363499 -0.04936375154296074 0.6252384595433996"/>
			<geometry>
				<mesh filename="textured_objs/original-33.obj"/>
			</geometry>
		</collision>
		<collision>
			<origin xyz="-0.007957159617363499 -0.04936375154296074 0.6252384595433996"/>
			<geometry>
				<mesh filename="textured_objs/original-34.obj"/>
			</geometry>
		</collision>
		<collision>
			<origin xyz="-0.007957159617363499 -0.04936375154296074 0.6252384595433996"/>
			<geometry>
				<mesh filename="textured_objs/original-40.obj"/>
			</geometry>
		</collision>
		<collision>
			<origin xyz="-0.007957159617363499 -0.04936375154296074 0.6252384595433996"/>
			<geometry>
				<mesh filename="textured_objs/original-49.obj"/>
			</geometry>
		</collision>
		<collision>
			<origin xyz="-0.007957159617363499 -0.04936375154296074 0.6252384595433996"/>
			<geometry>
				<mesh filename="textured_objs/original-48.obj"/>
			</geometry>
		</collision>
		<collision>
			<origin xyz="-0.007957159617363499 -0.04936375154296074 0.6252384595433996"/>
			<geometry>
				<mesh filename="textured_objs/original-47.obj"/>
			</geometry>
		</collision>
		<collision>
			<origin xyz="-0.007957159617363499 -0.04936375154296074 0.6252384595433996"/>
			<geometry>
				<mesh filename="textured_objs/original-46.obj"/>
			</geometry>
		</collision>
		<collision>
			<origin xyz="-0.007957159617363499 -0.04936375154296074 0.6252384595433996"/>
			<geometry>
				<mesh filename="textured_objs/original-45.obj"/>
			</geometry>
		</collision>
		<collision>
			<origin xyz="-0.007957159617363499 -0.04936375154296074 0.6252384595433996"/>
			<geometry>
				<mesh filename="textured_objs/original-44.obj"/>
			</geometry>
		</collision>
		<collision>
			<origin xyz="-0.007957159617363499 -0.04936375154296074 0.6252384595433996"/>
			<geometry>
				<mesh filename="textured_objs/original-43.obj"/>
			</geometry>
		</collision>
		<collision>
			<origin xyz="-0.007957159617363499 -0.04936375154296074 0.6252384595433996"/>
			<geometry>
				<mesh filename="textured_objs/original-41.obj"/>
			</geometry>
		</collision>
		<collision>
			<origin xyz="-0.007957159617363499 -0.04936375154296074 0.6252384595433996"/>
			<geometry>
				<mesh filename="textured_objs/original-42.obj"/>
			</geometry>
		</collision>
		<collision>
			<origin xyz="-0.007957159617363499 -0.04936375154296074 0.6252384595433996"/>
			<geometry>
				<mesh filename="textured_objs/original-50.obj"/>
			</geometry>
		</collision>
	</link>
	<joint name="joint_0" type="revolute">
		<origin xyz="0.0 0.0 0.0"/>
		<axis xyz="0.9874653220969688 -0.15783607477236022 0.00010562378449483896"/>
		<child link="link_0"/>
		<parent link="link_1"/>
		<limit lower="-0.10681415022205304" upper="2.670353755551324"/>
	</joint>
	<link name="link_1">
		<visual name="lid-2">
			<origin xyz="-0.007957159617363499 -0.04936375154296074 0.6252384595433996"/>
			<geometry>
				<mesh filename="textured_objs/original-37.obj"/>
			</geometry>
		</visual>
		<collision>
			<origin xyz="-0.007957159617363499 -0.04936375154296074 0.6252384595433996"/>
			<geometry>
				<mesh filename="textured_objs/original-37.obj"/>
			</geometry>
		</collision>
	</link>
	<joint name="joint_1" type="revolute">
		<origin xyz="0.007957159617363499 0.04936375154296074 -0.6252384595433996"/>
		<axis xyz="-0.9874653220969688 0.15783607477236022 -0.00010562378449483896"/>
		<child link="link_1"/>
		<parent link="link_2"/>
		<limit lower="-0.21991148575128555" upper="1.7592918860102844"/>
	</joint>
	<link name="link_2">
		<visual name="base_body-3">
			<origin xyz="0 0 0"/>
			<geometry>
				<mesh filename="textured_objs/original-36.obj"/>
			</geometry>
		</visual>
		<visual name="base_body-3">
			<origin xyz="0 0 0"/>
			<geometry>
				<mesh filename="textured_objs/original-3.obj"/>
			</geometry>
		</visual>
		<visual name="base_body-3">
			<origin xyz="0 0 0"/>
			<geometry>
				<mesh filename="textured_objs/original-2.obj"/>
			</geometry>
		</visual>
		<visual name="base_body-3">
			<origin xyz="0 0 0"/>
			<geometry>
				<mesh filename="textured_objs/original-8.obj"/>
			</geometry>
		</visual>
		<visual name="base_body-3">
			<origin xyz="0 0 0"/>
			<geometry>
				<mesh filename="textured_objs/original-5.obj"/>
			</geometry>
		</visual>
		<visual name="base_body-3">
			<origin xyz="0 0 0"/>
			<geometry>
				<mesh filename="textured_objs/original-6.obj"/>
			</geometry>
		</visual>
		<visual name="base_body-3">
			<origin xyz="0 0 0"/>
			<geometry>
				<mesh filename="textured_objs/original-7.obj"/>
			</geometry>
		</visual>
		<visual name="base_body-3">
			<origin xyz="0 0 0"/>
			<geometry>
				<mesh filename="textured_objs/original-1.obj"/>
			</geometry>
		</visual>
		<collision>
			<origin xyz="0 0 0"/>
			<geometry>
				<mesh filename="textured_objs/original-36.obj"/>
			</geometry>
		</collision>
		<collision>
			<origin xyz="0 0 0"/>
			<geometry>
				<mesh filename="textured_objs/original-3.obj"/>
			</geometry>
		</collision>
		<collision>
			<origin xyz="0 0 0"/>
			<geometry>
				<mesh filename="textured_objs/original-2.obj"/>
			</geometry>
		</collision>
		<collision>
			<origin xyz="0 0 0"/>
			<geometry>
				<mesh filename="textured_objs/original-8.obj"/>
			</geometry>
		</collision>
		<collision>
			<origin xyz="0 0 0"/>
			<geometry>
				<mesh filename="textured_objs/original-5.obj"/>
			</geometry>
		</collision>
		<collision>
			<origin xyz="0 0 0"/>
			<geometry>
				<mesh filename="textured_objs/original-6.obj"/>
			</geometry>
		</collision>
		<collision>
			<origin xyz="0 0 0"/>
			<geometry>
				<mesh filename="textured_objs/original-7.obj"/>
			</geometry>
		</collision>
		<collision>
			<origin xyz="0 0 0"/>
			<geometry>
				<mesh filename="textured_objs/original-1.obj"/>
			</geometry>
		</collision>
	</link>
	<joint name="joint_2" type="fixed">
		<origin rpy="1.570796326794897 0 -1.570796326794897" xyz="0 0 0"/>
		<child link="link_2"/>
		<parent link="base"/>
	</joint>
</robot>
